<?xml version="1.0" ?>
<!-- =================================================================================== -->
<!-- |    This document was autogenerated by xacro from camera_scene.xacro             | -->
<!-- |    EDITING THIS FILE BY HAND IS NOT RECOMMENDED                                 | -->
<!-- =================================================================================== -->
<robot name="data_aquisition" xmlns:xacro="http://ros.org/wiki/xacro">
  <link name="world_frame"/>
  <link name="target_frame">
    <visual>
      <origin xyz="0.6096  1.2192 0.0254"/>
      <geometry>
        <box size="1.2192  2.4384 0.0508"/>
      </geometry>
    </visual>
  </link>
  <link name="Basler1">
    <visual>
      <origin xyz=".01 .01 .01"/>
      <geometry>
        <box size=".02 .02 .02"/>
      </geometry>
    </visual>
  </link>
  <link name="Basler2">
    <visual>
      <origin xyz=".01 .01 .01"/>
      <geometry>
        <box size=".02 .02 .02"/>
      </geometry>
    </visual>
  </link>
  <joint name="$world_2_cal_target_joint" type="fixed">
    <parent link="world_frame"/>
    <child link="target_frame"/>
    <origin rpy="1.7104 0.0 1.5708" xyz="5.64 1.0  0.0"/>
  </joint>
  <link name="Basler1_x_trans">
    <visual>
      <origin rpy="0 0 0" xyz="0 0 0"/>
      <geometry>
        <sphere radius="0.0005"/>
      </geometry>
    </visual>
  </link>
  <link name="Basler1_y_trans"/>
  <link name="Basler1_z_trans"/>
  <link name="Basler1_pitch"/>
  <link name="Basler1_yaw"/>
  <joint name="Basler1_x_joint" type="prismatic">
    <parent link="world_frame"/>
    <child link="Basler1_x_trans"/>
    <origin rpy="0 0 0" xyz="0 0 0"/>
    <axis rpy="0 0 0" xyz="1 0 0"/>
    <limit effort="30" lower="-1.0" upper="1.0" velocity="0.0508"/>
  </joint>
  <joint name="Basler1_y_joint" type="prismatic">
    <parent link="Basler1_x_trans"/>
    <child link="Basler1_y_trans"/>
    <origin rpy="0 0 0" xyz="0 0 0"/>
    <axis rpy="0 0 0" xyz="0 1 0"/>
    <limit effort="30" lower="-1.0" upper="1.0" velocity="0.0508"/>
  </joint>
  <joint name="Basler1_z_joint" type="prismatic">
    <parent link="Basler1_y_trans"/>
    <child link="Basler1_z_trans"/>
    <origin rpy="0 0 0" xyz="0 0 0"/>
    <axis rpy="0 0 0" xyz="0 0 1"/>
    <limit effort="30" lower="-1.0" upper="1.0" velocity="0.0508"/>
  </joint>
  <joint name="Basler1_yaw_joint" type="revolute">
    <parent link="Basler1_z_trans"/>
    <child link="Basler1_yaw"/>
    <origin rpy="0 0 0" xyz="0 0 0"/>
    <limit effort="2" lower="-3.1415" upper="3.1415" velocity="10"/>
    <axis xyz="0 0 1"/>
  </joint>
  <joint name="Basler1_pitch_joint" type="revolute">
    <parent link="Basler1_yaw"/>
    <child link="Basler1_pitch"/>
    <origin rpy="0 0 0" xyz="0 0 0"/>
    <limit effort="2" lower="-3.1415" upper="3.1415" velocity="10"/>
    <axis xyz="0 1 0"/>
  </joint>
  <joint name="Basler1_roll_joint" type="revolute">
    <parent link="Basler1_pitch"/>
    <child link="Basler1"/>
    <origin rpy="0 0 0" xyz="0 0 0"/>
    <limit effort="2" lower="-3.1415" upper="3.1415" velocity="10"/>
    <axis xyz="1 0 0"/>
  </joint>
  <link name="Basler2_x_trans">
    <visual>
      <origin rpy="0 0 0" xyz="0 0 0"/>
      <geometry>
        <sphere radius="0.0005"/>
      </geometry>
    </visual>
  </link>
  <link name="Basler2_y_trans"/>
  <link name="Basler2_z_trans"/>
  <link name="Basler2_pitch"/>
  <link name="Basler2_yaw"/>
  <joint name="Basler2_x_joint" type="prismatic">
    <parent link="world_frame"/>
    <child link="Basler2_x_trans"/>
    <origin rpy="0 0 0" xyz="0 0 0"/>
    <axis rpy="0 0 0" xyz="1 0 0"/>
    <limit effort="30" lower="-1.0" upper="1.0" velocity="0.0508"/>
  </joint>
  <joint name="Basler2_y_joint" type="prismatic">
    <parent link="Basler2_x_trans"/>
    <child link="Basler2_y_trans"/>
    <origin rpy="0 0 0" xyz="0 0 0"/>
    <axis rpy="0 0 0" xyz="0 1 0"/>
    <limit effort="30" lower="-1.0" upper="1.0" velocity="0.0508"/>
  </joint>
  <joint name="Basler2_z_joint" type="prismatic">
    <parent link="Basler2_y_trans"/>
    <child link="Basler2_z_trans"/>
    <origin rpy="0 0 0" xyz="0 0 0"/>
    <axis rpy="0 0 0" xyz="0 0 1"/>
    <limit effort="30" lower="-1.0" upper="1.0" velocity="0.0508"/>
  </joint>
  <joint name="Basler2_yaw_joint" type="revolute">
    <parent link="Basler2_z_trans"/>
    <child link="Basler2_yaw"/>
    <origin rpy="0 0 0" xyz="0 0 0"/>
    <limit effort="2" lower="-3.1415" upper="3.1415" velocity="10"/>
    <axis xyz="0 0 1"/>
  </joint>
  <joint name="Basler2_pitch_joint" type="revolute">
    <parent link="Basler2_yaw"/>
    <child link="Basler2_pitch"/>
    <origin rpy="0 0 0" xyz="0 0 0"/>
    <limit effort="2" lower="-3.1415" upper="3.1415" velocity="10"/>
    <axis xyz="0 1 0"/>
  </joint>
  <joint name="Basler2_roll_joint" type="revolute">
    <parent link="Basler2_pitch"/>
    <child link="Basler2"/>
    <origin rpy="0 0 0" xyz="0 0 0"/>
    <limit effort="2" lower="-3.1415" upper="3.1415" velocity="10"/>
    <axis xyz="1 0 0"/>
  </joint>
  <material name="asus1dark_silver">
    <color rgba="0.15 0.15 0.15 1"/>
  </material>
  <link name="asus1_link"/>
  <link name="asus1_frame">
    <visual>
      <origin rpy="0 0 0" xyz="0 0 0"/>
      <geometry>
        <box size="0.04 0.22 0.04"/>
      </geometry>
      <material name="asus1dark_silver"/>
    </visual>
    <collision>
      <origin rpy="0 0 0" xyz="0 0 0"/>
      <geometry>
        <box size="0.04 0.22 0.04"/>
      </geometry>
    </collision>
  </link>
  <link name="asus1_ir_link">
    <visual>
      <origin rpy="0 0 0" xyz="0 0 0"/>
      <geometry>
        <sphere radius="0.0005"/>
      </geometry>
    </visual>
  </link>
  <link name="asus1_rgb_link">
    <visual>
      <origin rpy="0 0 0" xyz="0 0 0"/>
      <geometry>
        <sphere radius="0.0005"/>
      </geometry>
    </visual>
  </link>
  <link name="asus1_ir_optical_frame"/>
  <link name="asus1_rgb_optical_frame"/>
  <link name="asus1_link_x_trans">
    <visual>
      <origin rpy="0 0 0" xyz="0 0 0"/>
      <geometry>
        <sphere radius="0.0005"/>
      </geometry>
    </visual>
  </link>
  <link name="asus1_link_y_trans"/>
  <link name="asus1_link_z_trans"/>
  <link name="asus1_link_pitch"/>
  <link name="asus1_link_yaw"/>
  <joint name="asus1_link_x_joint" type="prismatic">
    <parent link="world_frame"/>
    <child link="asus1_link_x_trans"/>
    <origin rpy="0 0 0" xyz="0 0 0"/>
    <axis rpy="0 0 0" xyz="1 0 0"/>
    <limit effort="30" lower="-1.0" upper="1.0" velocity="0.0508"/>
  </joint>
  <joint name="asus1_link_y_joint" type="prismatic">
    <parent link="asus1_link_x_trans"/>
    <child link="asus1_link_y_trans"/>
    <origin rpy="0 0 0" xyz="0 0 0"/>
    <axis rpy="0 0 0" xyz="0 1 0"/>
    <limit effort="30" lower="-1.0" upper="1.0" velocity="0.0508"/>
  </joint>
  <joint name="asus1_link_z_joint" type="prismatic">
    <parent link="asus1_link_y_trans"/>
    <child link="asus1_link_z_trans"/>
    <origin rpy="0 0 0" xyz="0 0 0"/>
    <axis rpy="0 0 0" xyz="0 0 1"/>
    <limit effort="30" lower="-1.0" upper="1.0" velocity="0.0508"/>
  </joint>
  <joint name="asus1_link_yaw_joint" type="revolute">
    <parent link="asus1_link_z_trans"/>
    <child link="asus1_link_yaw"/>
    <origin rpy="0 0 0" xyz="0 0 0"/>
    <limit effort="2" lower="-3.1415" upper="3.1415" velocity="10"/>
    <axis xyz="0 0 1"/>
  </joint>
  <joint name="asus1_link_pitch_joint" type="revolute">
    <parent link="asus1_link_yaw"/>
    <child link="asus1_link_pitch"/>
    <origin rpy="0 0 0" xyz="0 0 0"/>
    <limit effort="2" lower="-3.1415" upper="3.1415" velocity="10"/>
    <axis xyz="0 1 0"/>
  </joint>
  <joint name="asus1_link_roll_joint" type="revolute">
    <parent link="asus1_link_pitch"/>
    <child link="asus1_link"/>
    <origin rpy="0 0 0" xyz="0 0 0"/>
    <limit effort="2" lower="-3.1415" upper="3.1415" velocity="10"/>
    <axis xyz="1 0 0"/>
  </joint>
  <joint name="asus1_frame_joint" type="fixed">
    <parent link="asus1_link"/>
    <child link="asus1_frame"/>
    <origin rpy="0 0 0" xyz="0 0 0"/>
  </joint>
  <joint name="asus1_ir_joint" type="fixed">
    <parent link="asus1_frame"/>
    <child link="asus1_ir_link"/>
    <origin rpy="0 0 0" xyz="0 0 0"/>
  </joint>
  <joint name="asus1_ir_optical_frame_joint" type="fixed">
    <parent link="asus1_ir_link"/>
    <child link="asus1_ir_optical_frame"/>
    <origin rpy="-1.57 0 -1.57" xyz="0 0 0"/>
  </joint>
  <joint name="asus1_rgb_joint" type="fixed">
    <parent link="asus1_ir_link"/>
    <child link="asus1_rgb_link"/>
    <origin rpy="0 0 0" xyz="0 -0.03 0"/>
  </joint>
  <joint name="asus1_rgb_optical_frame_joint" type="fixed">
    <parent link="asus1_rgb_link"/>
    <child link="asus1_rgb_optical_frame"/>
    <origin rpy="-1.57 0 -1.57" xyz="0 0 0"/>
  </joint>
  <material name="asus2dark_silver">
    <color rgba="0.15 0.15 0.15 1"/>
  </material>
  <link name="asus2_link"/>
  <link name="asus2_frame">
    <visual>
      <origin rpy="0 0 0" xyz="0 0 0"/>
      <geometry>
        <box size="0.04 0.22 0.04"/>
      </geometry>
      <material name="asus2dark_silver"/>
    </visual>
    <collision>
      <origin rpy="0 0 0" xyz="0 0 0"/>
      <geometry>
        <box size="0.04 0.22 0.04"/>
      </geometry>
    </collision>
  </link>
  <link name="asus2_ir_link">
    <visual>
      <origin rpy="0 0 0" xyz="0 0 0"/>
      <geometry>
        <sphere radius="0.0005"/>
      </geometry>
    </visual>
  </link>
  <link name="asus2_rgb_link">
    <visual>
      <origin rpy="0 0 0" xyz="0 0 0"/>
      <geometry>
        <sphere radius="0.0005"/>
      </geometry>
    </visual>
  </link>
  <link name="asus2_ir_optical_frame"/>
  <link name="asus2_rgb_optical_frame"/>
  <link name="asus2_link_x_trans">
    <visual>
      <origin rpy="0 0 0" xyz="0 0 0"/>
      <geometry>
        <sphere radius="0.0005"/>
      </geometry>
    </visual>
  </link>
  <link name="asus2_link_y_trans"/>
  <link name="asus2_link_z_trans"/>
  <link name="asus2_link_pitch"/>
  <link name="asus2_link_yaw"/>
  <joint name="asus2_link_x_joint" type="prismatic">
    <parent link="world_frame"/>
    <child link="asus2_link_x_trans"/>
    <origin rpy="0 0 0" xyz="0 0 0"/>
    <axis rpy="0 0 0" xyz="1 0 0"/>
    <limit effort="30" lower="-1.0" upper="1.0" velocity="0.0508"/>
  </joint>
  <joint name="asus2_link_y_joint" type="prismatic">
    <parent link="asus2_link_x_trans"/>
    <child link="asus2_link_y_trans"/>
    <origin rpy="0 0 0" xyz="0 0 0"/>
    <axis rpy="0 0 0" xyz="0 1 0"/>
    <limit effort="30" lower="-1.0" upper="1.0" velocity="0.0508"/>
  </joint>
  <joint name="asus2_link_z_joint" type="prismatic">
    <parent link="asus2_link_y_trans"/>
    <child link="asus2_link_z_trans"/>
    <origin rpy="0 0 0" xyz="0 0 0"/>
    <axis rpy="0 0 0" xyz="0 0 1"/>
    <limit effort="30" lower="-1.0" upper="1.0" velocity="0.0508"/>
  </joint>
  <joint name="asus2_link_yaw_joint" type="revolute">
    <parent link="asus2_link_z_trans"/>
    <child link="asus2_link_yaw"/>
    <origin rpy="0 0 0" xyz="0 0 0"/>
    <limit effort="2" lower="-3.1415" upper="3.1415" velocity="10"/>
    <axis xyz="0 0 1"/>
  </joint>
  <joint name="asus2_link_pitch_joint" type="revolute">
    <parent link="asus2_link_yaw"/>
    <child link="asus2_link_pitch"/>
    <origin rpy="0 0 0" xyz="0 0 0"/>
    <limit effort="2" lower="-3.1415" upper="3.1415" velocity="10"/>
    <axis xyz="0 1 0"/>
  </joint>
  <joint name="asus2_link_roll_joint" type="revolute">
    <parent link="asus2_link_pitch"/>
    <child link="asus2_link"/>
    <origin rpy="0 0 0" xyz="0 0 0"/>
    <limit effort="2" lower="-3.1415" upper="3.1415" velocity="10"/>
    <axis xyz="1 0 0"/>
  </joint>
  <joint name="asus2_frame_joint" type="fixed">
    <parent link="asus2_link"/>
    <child link="asus2_frame"/>
    <origin rpy="0 0 0" xyz="0 0 0"/>
  </joint>
  <joint name="asus2_ir_joint" type="fixed">
    <parent link="asus2_frame"/>
    <child link="asus2_ir_link"/>
    <origin rpy="0 0 0" xyz="0 0 0"/>
  </joint>
  <joint name="asus2_ir_optical_frame_joint" type="fixed">
    <parent link="asus2_ir_link"/>
    <child link="asus2_ir_optical_frame"/>
    <origin rpy="-1.57 0 -1.57" xyz="0 0 0"/>
  </joint>
  <joint name="asus2_rgb_joint" type="fixed">
    <parent link="asus2_ir_link"/>
    <child link="asus2_rgb_link"/>
    <origin rpy="0 0 0" xyz="0 -0.03 0"/>
  </joint>
  <joint name="asus2_rgb_optical_frame_joint" type="fixed">
    <parent link="asus2_rgb_link"/>
    <child link="asus2_rgb_optical_frame"/>
    <origin rpy="-1.57 0 -1.57" xyz="0 0 0"/>
  </joint>
</robot>

